2024-08-09 19:55:52,763 ERROR 155 biostarPython Cannot get search device: <_InactiveRpcError of RPC that terminated with:
	status = StatusCode.UNAVAILABLE
	details = "failed to connect to all addresses; last error: UNAVAILABLE: ipv4:127.0.0.1:4000: ConnectEx: Connection refused (No connection could be made because the target machine actively refused it.
 -- 10061)"
	debug_error_string = "UNKNOWN:Error received from peer  {grpc_message:"failed to connect to all addresses; last error: UNAVAILABLE: ipv4:127.0.0.1:4000: ConnectEx: Connection refused (No connection could be made because the target machine actively refused it.\r\n -- 10061)", grpc_status:14, created_time:"2024-08-09T18:55:52.7518082+00:00"}"
>
2024-08-09 19:56:01,009 ERROR 155 biostarPython Cannot get search device: <_InactiveRpcError of RPC that terminated with:
	status = StatusCode.UNAVAILABLE
	details = "failed to connect to all addresses; last error: UNAVAILABLE: ipv4:127.0.0.1:4000: ConnectEx: Connection refused (No connection could be made because the target machine actively refused it.
 -- 10061)"
	debug_error_string = "UNKNOWN:Error received from peer  {created_time:"2024-08-09T18:56:00.9974617+00:00", grpc_status:14, grpc_message:"failed to connect to all addresses; last error: UNAVAILABLE: ipv4:127.0.0.1:4000: ConnectEx: Connection refused (No connection could be made because the target machine actively refused it.\r\n -- 10061)"}"
>
2024-08-09 20:01:20,564 ERROR 169 biostarPython Cannot connect to the device: <_InactiveRpcError of RPC that terminated with:
	status = StatusCode.UNAVAILABLE
	details = "Cannot connect to the device: dial tcp 192.168.0.105:0->192.168.3.117:51211: connectex: A connection attempt failed because the connected party did not properly respond after a period of time, or established connection failed because connected host has failed to respond."
	debug_error_string = "UNKNOWN:Error received from peer  {created_time:"2024-08-09T19:01:20.5517793+00:00", grpc_status:14, grpc_message:"Cannot connect to the device: dial tcp 192.168.0.105:0->192.168.3.117:51211: connectex: A connection attempt failed because the connected party did not properly respond after a period of time, or established connection failed because connected host has failed to respond."}"
>
2024-08-09 20:02:49,844 ERROR 957 biostarPython Cannot get the Custom config: <_InactiveRpcError of RPC that terminated with:
	status = StatusCode.INTERNAL
	details = "Cannot get custom card config: No data for config"
	debug_error_string = "UNKNOWN:Error received from peer  {created_time:"2024-08-09T19:02:49.8323617+00:00", grpc_status:13, grpc_message:"Cannot get custom card config: No data for config"}"
>
